<?xml version="1.0" ?>
<!-- =================================================================================== -->
<!-- |    This document was autogenerated by xacro from Sur10.urdf.xacro               | -->
<!-- |    EDITING THIS FILE BY HAND IS NOT RECOMMENDED                                 | -->
<!-- =================================================================================== -->
<robot  name="ur10" xmlns:xacro="http://ros.org/wiki/xacro">

  <!-- <link name="base_link" >
    <visual>
      <geometry>
        <mesh filename="package://ur_description/meshes/ur10/visual/base.dae"/>
      </geometry>
      <material name="Blah">
        <color rgba="1.0 1.0 1.0 1.0"/>
      </material>
    </visual>
    <collision>
      <geometry>
        <mesh filename="package://ur_description/meshes/ur10/collision/base.stl"/>
      </geometry>
    </collision>
    <xacro:cylinder_inertial radius="0.075" length="0.038" mass="4.0">
      <origin xyz="0.0 0.0 0.0" rpy="0 0 0" />
    </xacro:cylinder_inertial>
  </link> -->

  <link name="arm_shoulder_1_link">
    <visual>
      <geometry>
        <box size="0.07 0.07 0.1"/>
      </geometry>
      <origin rpy="0 0 0" xyz="0 0 0"/>
      <material name="ShoulderColour">
        <color rgba="0.4 0.4 0.4 1.0"/>
      </material>
    </visual>
    <collision>
      <geometry>
        <box size="0.05 0.05 0.05"/>
      </geometry>
      <origin rpy="0 0 0" xyz="0 0 0"/>
    </collision>
  </link>

  <joint name="arm_shoulder_1_joint" type="revolute">
    <parent link="arm_shoulder_1_link" />
    <child link = "arm_shoulder_2_link" />
    <origin xyz="0.0 0.0 0.0" rpy="0.0 0.0 0.0" />
    <axis xyz="0 1 0" />
    <limit lower="-3.14159265" upper="3.14159265" effort="54.0" velocity="3.2"/>
    <dynamics damping="0.0" friction="0.0"/>
  </joint>

  <link name="arm_shoulder_2_link">
    <visual>
      <geometry>
        <box size="0.01 0.01 0.01"/>
      </geometry>
      <origin rpy="0 0 0" xyz="0 0 0"/>
      <material name="ShoulderColour">
        <color rgba="0.4 0.4 0.4 1.0"/>
      </material>
    </visual>
    <collision>
      <geometry>
        <box size="0.05 0.05 0.05"/>
      </geometry>
      <origin rpy="0 0 0" xyz="0 0 0"/>
    </collision>
  </link>

  <joint name="arm_shoulder_2_joint" type="revolute">
    <parent link="arm_shoulder_2_link" />
    <child link = "arm_upper_arm_link" />
    <origin xyz="0.0 0.0 0.0" rpy="0.0 0.0 0.0" />
    <axis xyz="0 0 1" />
    <limit lower="-3.14159265" upper="3.14159265" effort="54.0" velocity="3.2"/>
    <dynamics damping="0.0" friction="0.0"/>
  </joint>

  <link name="arm_upper_arm_link">
    <visual>
      <geometry>
        <cylinder length="0.3" radius="0.035"/>
      </geometry>
      <origin rpy="0 1.570796 0" xyz="0.15 0 0"/>
      <material name="Elbow">
        <color rgba="0.2 0.2 0.2 1.0"/>
      </material>
    </visual>
    <collision>
      <geometry>
        <cylinder length="0.3" radius="0.035"/>
      </geometry>
      <origin rpy="0 1.570796 0" xyz="0.15 0 0"/>
    </collision>
  </link>

  <joint name="arm_elbow_1_joint" type="revolute">
    <parent link="arm_upper_arm_link" />
    <child link = "arm_forearm_1_link" />
    <origin xyz="0.3 0.0 0.0" rpy="0.0 0.0 0.0" />
    <axis xyz="0 0 1" />
    <limit lower="-3.14159265" upper="3.14159265" effort="54.0" velocity="3.2"/>
    <dynamics damping="0.0" friction="0.0"/>
  </joint>

  <link name="arm_forearm_1_link">
    <visual>
      <geometry>
        <cylinder length="0.25" radius="0.025"/>
      </geometry>
      <origin rpy="0 1.570796 0" xyz="0.125 0.0 0.0"/>
      <material name="FA">
        <color rgba="0.0 0.0 0.0 1.0"/>
      </material>
    </visual>
    <collision>
      <geometry>
        <cylinder length="0.25" radius="0.025"/>
      </geometry>
      <origin rpy="0 1.570796 0" xyz="0.125 0.0 0.0"/>
    </collision>
    <!-- <inertial>
      <mass value="1.80"/>
      <inertia ixx="0.4" ixy="0.0" ixz="0.0" iyy="0.4" iyz="0.0" izz="0.2"/>
      <origin xyz="0.0 0.0 0.0" rpy="0 0 0" />
    </inertial> -->
  </link>

  <link name="world" />

  <joint name="world_joint" type="fixed">
    <parent link="world" />
    <child link = "arm_shoulder_1_link" />
    <origin xyz="0.0 0.0 0.0" rpy="0.0 0.0 0.0" />
  </joint>


  <!-- <joint name="shoulder_pan_joint" type="revolute">
    <parent link="base_link" />
    <child link = "shoulder_link" />
    <origin xyz="0.0 0.0 0.1273" rpy="0.0 0.0 0.0" />
    <axis xyz="0 0 1" />
    <limit lower="-3.1415" upper="3.1415" effort="330.0" velocity="2.16"/>
    <dynamics damping="0.0" friction="0.0"/>
  </joint>

  <link name="shoulder_link">
    <visual>
      <geometry>
        <mesh filename="package://ur_description/meshes/ur10/visual/shoulder.dae"/>
      </geometry>
      <material name="LightGrey">
        <color rgba="0.7 0.7 0.7 1.0"/>
      </material>
    </visual>
    <collision>
      <geometry>
        <mesh filename="package://ur_description/meshes/ur10/collision/shoulder.stl"/>
      </geometry>
    </collision>
    <xacro:cylinder_inertial radius="0.075" length="0.178" mass="7.778">
      <origin xyz="0.0 0.0 0.0" rpy="0 0 0" />
    </xacro:cylinder_inertial>
  </link> -->

</robot>
